Workbook

Sheet 摘要与结论
A1: 臻陶科技 · 泛半导体陶瓷材料及部件
A2: 一级市场估值模型（天使轮）｜多方法交叉验证
A3: 估值基准日 2026-06 ｜ 单位：人民币万元 ｜ 资料：项目BP（2026.6规划口径）
A5: 一、估值结论（投前 Pre-money，万元）
A6: 估值方法 | B6: 投前估值 | C6: 权重 | D6: 加权贡献 | E6: 说明
A7: VC Method（概率加权） | B7: ='VC Method'!B34 | C7: 0.4 | D7: =B7*C7 | E7: 退出营收×PS倍数(折价)，反推本轮投后
A8: Scorecard（计分卡） | B8: =Scorecard!B18 | C8: 0.3 | D8: =B8*C8 | E8: 行业基准×加权得分
A9: Berkus（伯克斯） | B9: =Berkus!B14 | C9: 0.2 | D9: =B9*C9 | E9: 五要素定性赋值（硬科技×0.9系数）
A10: 可比PS倍数参考 | B10: =可比估值!B20 | C10: 0.1 | D10: =B10*C10 | E10: 近端营收×早期PS（交叉校验）
A11: 加权投前估值 | B11: =SUMPRODUCT(B7:B10,C7:C10) | C11: =SUM(C7:C10) | D11: =SUM(D7:D10) | E11: 各方法按权重合成
A13: 二、估值区间与本轮融资建议
A14: 投前估值区间（低-高） | B14: =MIN(B7:B10) | C14: 至 | D14: =MAX(B7:B10) | E14: 取各方法区间
A15: 建议投前估值（中枢） | B15: =B11 | C15: 本轮投资额 | D15: 4500 | E15: 投后=投前+投资额
A16: 建议投后估值（中枢） | B16: =B15+D15 | C16: 本轮股比 | D16: =D15/B16 | E16: 投资额/投后估值
A18: 注：本模型为基于BP的分析性估值，非审计或正式评估。BP未提供审计财务、订单合同、资产负债表与股权结构，所有折现率、倍数、稀释、概率均为分析师判断，需在尽调中以管理层三表模型与第三方材料替换。不构成投资建议。

Sheet VC Method
A1: VC Method（风险资本法）· 概率加权
A2: 退出价值 = 退出营收 × PS倍数(折价)；所需股比 = 投资×MOIC / 退出价值；投后 = 投资 / 所需股比 ÷ (1-后续稀释)。单位：万元。
A4: 一、通用输入
A5: 本轮投资额（万元） | B5: 4500
A6: 退出年份 | B6: 2031
A7: 退出年营收-BP口径（万元） | B7: 100000
A8: 目标MOIC（倍） | B8: 8
A9: 可比上市公司PS倍数（EV/Rev） | B9: 8
A11: 二、三情景假设（乐观/基准/悲观）
A12: 参数 | B12: 乐观 | C12: 基准 | D12: 悲观 | E12: 加权 | F12: 说明
A13: 退出营收乘数（×BP） | B13: 1.25 | C13: 1 | D13: 0.6 | F13: 退出营收=BP×乘数
A14: 退出PS折价系数（×可比PS） | B14: 0.75 | C14: 0.6 | D14: 0.2 | F14: 退出PS=可比PS×折价
A15: 至IPO累计稀释率 | B15: 0.45 | C15: 0.55 | D15: 0.65 | F15: 本轮股比被后续摊薄
A16: 情景概率 | B16: 0.2 | C16: 0.55 | D16: 0.25 | E16: =B16+C16+D16 | F16: 三概率合计应=100%
A18: 三、各情景计算
A19: 计算项 | B19: 乐观 | C19: 基准 | D19: 悲观 | E19: 概率加权
A20: 退出营收（万元） | B20: =$B$7*B13 | C20: =$B$7*C13 | D20: =$B$7*D13 | E20: =B20*B$16+C20*C$16+D20*D$16
A21: 退出PS倍数（x） | B21: =$B$9*B14 | C21: =$B$9*C14 | D21: =$B$9*D14 | E21: =B21*B$16+C21*C$16+D21*D$16
A22: 退出股权价值（万元） | B22: =B20*B21 | C22: =C20*C21 | D22: =D20*D21 | E22: =B22*B$16+C22*C$16+D22*D$16
A23: 要求退出收益（万元） | B23: =$B$5*$B$8 | C23: =$B$5*$B$8 | D23: =$B$5*$B$8 | E23: =$B$5*$B$8
A24: 退出时所需股比 | B24: =B23/B22 | C24: =C23/C22 | D24: =D23/D22 | E24: =E23/E22
A25: 本轮所需股比（还原稀释） | B25: =B24/(1-B15) | C25: =C24/(1-C15) | D25: =D24/(1-D15) | E25: =E24/(1-(B15*B$16+C15*C$16+D15*D$16))
A26: 可投性（股比<50%） | B26: =IF(B25<0.5,"可投","过高") | C26: =IF(C25<0.5,"可投","过高") | D26: =IF(D25<0.5,"可投","过高") | E26: =IF(E25<0.5,"可投","过高")
A27: 隐含投后估值（万元） | B27: =$B$5/B25 | C27: =$B$5/C25 | D27: =$B$5/D25 | E27: =$B$5/E25
A28: 隐含投前估值（万元） | B28: =B27-$B$5 | C28: =C27-$B$5 | D28: =D27-$B$5 | E28: =E27-$B$5
A30: 四、VC Method 估值结论
A31: 概率加权退出股权价值 | B31: =E22 | C31: 概率加权所需股比 | D31: =E25
A32: 概率加权投后估值 | B32: =E27 | C32: 本轮投资额 | D32: =B5
A33: 概率加权投前估值 | B33: =E28
A34: VC Method 投前估值（用于汇总） | B34: =E28
A36: 注：可比PS倍数交叉校验（近端营收×早期PS）已独立至「可比估值」表，详见该表。

Sheet Scorecard
A1: Scorecard Method（计分卡法）
A2: 投前 = 行业基准投前估值 × 加权得分（100%=行业平均）。单位：万元。
A4: 一、基准与维度打分
A5: 半导体/硬科技 天使轮基准投前（万元） | B5: 9000
A7: 维度 | B7: 权重 | C7: 得分 | D7: 加权 | E7: 打分理由
A8: 团队质量 | B8: 0.3 | C8: 1.5 | D8: =B8*C8 | E8: 李明远教授(世界前1%材料学者,国家级领军人才)领衔;核心团队含30年半导体大厂经验,团队完整。显著优于均值。
A9: 市场规模 | B9: 0.25 | C9: 1.3 | D9: =B9*C9 | E9: MCS/ESC/加热器/Si3N4合计数十亿美元级,国产替代迫切,TAM大且增长。优于均值。
A10: 产品/技术 | B10: 0.15 | C10: 1.4 | D10: =B10*C10 | E10: 共键合原创工艺,实测键合强度≥310MPa、Si3N4热导率超日本;发明专利2项+专有技术。高壁垒。
A11: 竞争环境 | B11: 0.1 | C11: 1.2 | D11: =B11*C11 | E11: 高端MCS近乎日本垄断,国内空白;技术差异化明显,但需验证可复制良率。略优。
A12: 市场/销售 | B12: 0.1 | C12: 1 | D12: =B12*C12 | E12: 已与华芯国际、北方精创等头部沟通,尚无签约订单与量产验证。中性。
A13: 其他(政策/退出) | B13: 0.1 | C13: 1.2 | D13: =B13*C13 | E13: 卡脖子赛道政策强支持,科创板退出通道明确;但认证周期长、资本密集。略优。
A14: 合计 | B14: =SUM(B8:B13) | D14: =SUM(D8:D13) | E14: 加权得分
A16: 二、Scorecard 估值结论
A17: 行业基准投前（万元） | B17: =B5
A18: Scorecard 投前估值（万元） | B18: =B5*D14

Sheet Berkus
A1: Berkus Method（伯克斯法）
A2: 投前 = 五要素赋值之和 × 行业系数。适用最早期项目。单位：万元。
A4: 一、五要素赋值
A5: 要素 | B5: 赋值(万元) | C5: 上限(万元) | D5: 理由
A6: 合理创意/商业价值 | B6: 90 | C6: 100 | D6: 卡脖子材料国产替代,商业价值验证充分,接近上限。
A7: 原型产品/技术验证 | B7: 180 | C7: 200 | D7: 已制备2英寸/6英寸样品,Micro-CT无缺陷,接近上限。
A8: 优质团队 | B8: 280 | C8: 300 | D8: 顶尖科学家+完整产业化团队,接近上限。
A9: 战略关系 | B9: 110 | C9: 150 | D9: 与华芯国际、北方精创等头部沟通中,尚未签约。
A10: 产品发布/销售 | B10: 60 | C10: 250 | D10: 尚处小批量/送样验证阶段,无规模销售。
A11: 要素赋值合计 | B11: =SUM(B6:B10) | C11: =SUM(C6:C10) | D11: 基础值(未乘行业系数)
A12: 行业系数(硬件/制造) | B12: 0.9
A13: 二、Berkus 估值结论
A14: Berkus 投前估值（万元） | B14: =B11*B12
A15: 注：Berkus 天使轮总上限有限,对深科技项目通常偏保守,故仅赋20%权重。

Sheet 可比估值
A1: 可比估值（Comparable Company Analysis · PS 倍数法）
A2: 以可比上市公司 EV/Revenue（市销率PS）为锚，对臻陶科技做近端PS交叉校验，作为估值区间上沿参照。单位：万元（除倍数）。
A4: 一、可比上市公司 EV/Revenue 倍数
A5: 公司 | B5: 领域 | C5: EV/Revenue(x) | D5: 备注
A6: 富创精密 | B6: 半导体设备精密零部件 | C6: 9 | D6: 半导体零部件平台型企业
A7: 珂玛科技 | B7: 半导体陶瓷零部件 | C7: 11 | D7: 陶瓷材料与结构件
A8: 华卓精科 | B8: 精密运动系统 | C8: 12 | D8: 光刻机精密运动台
A9: 神工股份 | B9: 半导体级硅材料 | C9: 7 | D9: 刻蚀用硅零部件
A10: 行业中位 | B10: 半导体零部件板块 | C10: 8 | D10: 报告采用锚点
A12: 二、倍数统计
A13: 区间下沿 | B13: =MIN(C6:C9) | C13: 至 | D13: =MAX(C6:C9) | E13: 可比区间 7-12x
A14: 行业中位 | B14: =C10 | E14: 报告口径约 8x
A15: 简单均值 | B15: =AVERAGE(C6:C9) | E15: 四家可比均值 ≈9.75x（供参考）
A17: 三、可比估值推导（近端营收 × 早期PS倍数）
A18: 近端营收 2028E（万元） | B18: 3000
A19: 采用PS倍数（x） | B19: 12
A20: 可比PS隐含投前估值（万元） | B20: =B18*B19
A21: 对应（亿元） | B21: =B20/10000
A23: 校验口径：以近端营收×早期PS倍数近似当期股权价值，作为VC Method的横向参照，构成估值区间上沿（3.6亿元）；若按行业中位8x，则对应约2.4亿元的保守参照。

Sheet DCF
A1: 情景 DCF（无杠杆自由现金流）· 内在价值交叉校验
A2: 早期深科技用高WACC吸收执行/生存风险（不再单独乘生存概率，避免重复计风险）。单位：万元；括号为流出。
A4: 情景选择器 (1=熊 2=基准 3=牛) | B4: 2
A5: 当前情景 | B5: =CHOOSE($B$4,"熊市 Bear","基准 Base","牛市 Bull")
A6: 一、情景假设与选择（营收乘数×BP / EBIT利润率）
A7: 假设 \ 年份 | B7: 2027E | C7: 2028E | D7: 2029E | E7: 2030E | F7: 2031E
A8: 熊市·营收乘数 | B8: 0.6 | C8: 0.6 | D8: 0.6 | E8: 0.6 | F8: 0.6
A9: 熊市·EBIT利润率 | B9: -1 | C9: -0.5 | D9: -0.15 | E9: 0.05 | F9: 0.15
A10: 基准·营收乘数 | B10: 1 | C10: 1 | D10: 1 | E10: 1 | F10: 1
A11: 基准·EBIT利润率 | B11: -0.8 | C11: -0.3 | D11: 0 | E11: 0.12 | F11: 0.22
A12: 牛市·营收乘数 | B12: 1.25 | C12: 1.25 | D12: 1.25 | E12: 1.25 | F12: 1.25
A13: 牛市·EBIT利润率 | B13: -0.6 | C13: -0.15 | D13: 0.08 | E13: 0.2 | F13: 0.3
A14: ▶ 选中·营收乘数 | B14: =CHOOSE($B$4,B8,B10,B12) | C14: =CHOOSE($B$4,C8,C10,C12) | D14: =CHOOSE($B$4,D8,D10,D12) | E14: =CHOOSE($B$4,E8,E10,E12) | F14: =CHOOSE($B$4,F8,F10,F12)
A15: ▶ 选中·EBIT利润率 | B15: =CHOOSE($B$4,B9,B11,B13) | C15: =CHOOSE($B$4,C9,C11,C13) | D15: =CHOOSE($B$4,D9,D11,D13) | E15: =CHOOSE($B$4,E9,E11,E13) | F15: =CHOOSE($B$4,F9,F11,F13)
A17: 二、收入与自由现金流（万元）
A18: 项目 \ 年份 | B18: 2027E | C18: 2028E | D18: 2029E | E18: 2030E | F18: 2031E
A19: BP营收路径 | B19: 350 | C19: 3000 | D19: 30000 | E19: 50000 | F19: 100000
A20: 情景营收 | B20: =B19*B14 | C20: =C19*C14 | D20: =D19*D14 | E20: =E19*E14 | F20: =F19*F14
A21: 营收增速 | B21: n/a | C21: =C20/B20-1 | D21: =D20/C20-1 | E21: =E20/D20-1 | F21: =F20/E20-1
A22: EBIT利润率(选中) | B22: =B15 | C22: =C15 | D22: =D15 | E22: =E15 | F22: =F15
A23: EBIT | B23: =B20*B22 | C23: =C20*C22 | D23: =D20*D22 | E23: =E20*E22 | F23: =F20*F22
A24: 所得税 | B24: =-MAX(B23,0)*$B$33 | C24: =-MAX(C23,0)*$B$33 | D24: =-MAX(D23,0)*$B$33 | E24: =-MAX(E23,0)*$B$33 | F24: =-MAX(F23,0)*$B$33
A25: NOPAT | B25: =B23+B24 | C25: =C23+C24 | D25: =D23+D24 | E25: =E23+E24 | F25: =F23+F24
A26: (+) 折旧摊销 | B26: =B20*$B$34 | C26: =C20*$B$34 | D26: =D20*$B$34 | E26: =E20*$B$34 | F26: =F20*$B$34
A27: (-) 资本开支 | B27: =B20*$B$35 | C27: =C20*$B$35 | D27: =D20*$B$35 | E27: =E20*$B$35 | F27: =F20*$B$35
A28: (-) 营运资金增加 | B28: =B20*$B$36 | C28: =(C20-B20)*$B$36 | D28: =(D20-C20)*$B$36 | E28: =(E20-D20)*$B$36 | F28: =(F20-E20)*$B$36
A29: 无杠杆自由现金流 UFCF | B29: =B25+B26-B27-B28 | C29: =C25+C26-C27-C28 | D29: =D25+D26-D27-D28 | E29: =E25+E26-E27-E28 | F29: =F25+F26-F27-F28
A31: 三、DCF 参数（估值假设）
A32: WACC (一级市场,含创业风险) | B32: =CHOOSE($B$4,0.22,0.18,0.15) | C32: 熊22%/基准18%/牛15%
A33: 所得税率 | B33: 0.15
A34: 折旧摊销 %营收 | B34: 0.08
A35: 资本开支 %营收 | B35: 0.12
A36: 营运资金增加 %营收增量 | B36: 0.15
A37: 永续增长率 g | B37: =CHOOSE($B$4,0.02,0.03,0.04) | C37: 熊2%/基准3%/牛4%
A38: 净债务（万元） | B38: 0
A40: 四、折现与企业价值（年中折现）
A41: 项目 \ 年份 | B41: 2027E | C41: 2028E | D41: 2029E | E41: 2030E | F41: 2031E | G41: 终值
A42: UFCF | B42: =B29 | C42: =C29 | D42: =D29 | E42: =E29 | F42: =F29
A43: 折现期(年中) | B43: 0.5 | C43: 1.5 | D43: 2.5 | E43: 3.5 | F43: 4.5
A44: 折现因子 | B44: =1/(1+$B$32)^B43 | C44: =1/(1+$B$32)^C43 | D44: =1/(1+$B$32)^D43 | E44: =1/(1+$B$32)^E43 | F44: =1/(1+$B$32)^F43
...

Sheet 敏感性分析
A1: 敏感性分析
A3: 表1：VC Method 投前估值（万元）= f(目标MOIC × 可比PS倍数)
A4: 行=MOIC ↓ / 列=可比PS → | B4: 6 | C4: 7 | D4: 8 | E4: 9 | F4: 10
A5: 6 | B5: ='VC Method'!B5/((('VC Method'!B5*$A5)/('VC Method'!B7*'VC Method'!B13*(B$4*'VC Method'!B14)*'VC Method'!B16+'VC Method'!B7*'VC Method'!C13*(B$4*'VC Method'!C14)*'VC Method'!C16+'VC Method'!B7*'VC Method'!D13*(B$4*'VC Method'!D14)*'VC Method'!D16))/(1-('VC Method'!B15*'VC Method'!B16+'VC Method'!C15*'VC Method'!C16+'VC Method'!D15*'VC Method'!D16)))-'VC Method'!B5 | C5: ='VC Method'!B5/((('VC Method'!B5*$A5)/('VC Method'!B7*'VC Method'!B13*(C$4*'VC Method'!B14)*'VC Method'!B16+'VC Method'!B7*'VC Method'!C13*(C$4*'VC Method'!C14)*'VC Method'!C16+'VC Method'!B7*'VC Method'!D13*(C$4*'VC Method'!D14)*'VC Method'!D16))/(1-('VC Method'!B15*'VC Method'!B16+'VC Method'!C15*'VC Method'!C16+'VC Method'!D15*'VC Method'!D16)))-'VC Method'!B5 | D5: ='VC Method'!B5/((('VC Method'!B5*$A5)/('VC Method'!B7*'VC Method'!B13*(D$4*'VC Method'!B14)*'VC Method'!B16+'VC Method'!B7*'VC Method'!C13*(D$4*'VC Method'!C14)*'VC Method'!C16+'VC Method'!B7*'VC Method'!D13*(D$4*'VC Method'!D14)*'VC Method'!D16))/(1-('VC Method'!B15*'VC Method'!B16+'VC Method'!C15*'VC Method'!C16+'VC Method'!D15*'VC Method'!D16)))-'VC Method'!B5 | E5: ='VC Method'!B5/((('VC Method'!B5*$A5)/('VC Method'!B7*'VC Method'!B13*(E$4*'VC Method'!B14)*'VC Method'!B16+'VC Method'!B7*'VC Method'!C13*(E$4*'VC Method'!C14)*'VC Method'!C16+'VC Method'!B7*'VC Method'!D13*(E$4*'VC Method'!D14)*'VC Method'!D16))/(1-('VC Method'!B15*'VC Method'!B16+'VC Method'!C15*'VC Method'!C16+'VC Method'!D15*'VC Method'!D16)))-'VC Method'!B5 | F5: ='VC Method'!B5/((('VC Method'!B5*$A5)/('VC Method'!B7*'VC Method'!B13*(F$4*'VC Method'!B14)*'VC Method'!B16+'VC Method'!B7*'VC Method'!C13*(F$4*'VC Method'!C14)*'VC Method'!C16+'VC Method'!B7*'VC Method'!D13*(F$4*'VC Method'!D14)*'VC Method'!D16))/(1-('VC Method'!B15*'VC Method'!B16+'VC Method'!C15*'VC Method'!C16+'VC Method'!D15*'VC Method'!D16)))-'VC Method'!B5
A6: 7 | B6: ='VC Method'!B5/((('VC Method'!B5*$A6)/('VC Method'!B7*'VC Method'!B13*(B$4*'VC Method'!B14)*'VC Method'!B16+'VC Method'!B7*'VC Method'!C13*(B$4*'VC Method'!C14)*'VC Method'!C16+'VC Method'!B7*'VC Method'!D13*(B$4*'VC Method'!D14)*'VC Method'!D16))/(1-('VC Method'!B15*'VC Method'!B16+'VC Method'!C15*'VC Method'!C16+'VC Method'!D15*'VC Method'!D16)))-'VC Method'!B5 | C6: ='VC Method'!B5/((('VC Method'!B5*$A6)/('VC Method'!B7*'VC Method'!B13*(C$4*'VC Method'!B14)*'VC Method'!B16+'VC Method'!B7*'VC Method'!C13*(C$4*'VC Method'!C14)*'VC Method'!C16+'VC Method'!B7*'VC Method'!D13*(C$4*'VC Method'!D14)*'VC Method'!D16))/(1-('VC Method'!B15*'VC Method'!B16+'VC Method'!C15*'VC Method'!C16+'VC Method'!D15*'VC Method'!D16)))-'VC Method'!B5 | D6: ='VC Method'!B5/((('VC Method'!B5*$A6)/('VC Method'!B7*'VC Method'!B13*(D$4*'VC Method'!B14)*'VC Method'!B16+'VC Method'!B7*'VC Method'!C13*(D$4*'VC Method'!C14)*'VC Method'!C16+'VC Method'!B7*'VC Method'!D13*(D$4*'VC Method'!D14)*'VC Method'!D16))/(1-('VC Method'!B15*'VC Method'!B16+'VC Method'!C15*'VC Method'!C16+'VC Method'!D15*'VC Method'!D16)))-'VC Method'!B5 | E6: ='VC Method'!B5/((('VC Method'!B5*$A6)/('VC Method'!B7*'VC Method'!B13*(E$4*'VC Method'!B14)*'VC Method'!B16+'VC Method'!B7*'VC Method'!C13*(E$4*'VC Method'!C14)*'VC Method'!C16+'VC Method'!B7*'VC Method'!D13*(E$4*'VC Method'!D14)*'VC Method'!D16))/(1-('VC Method'!B15*'VC Method'!B16+'VC Method'!C15*'VC Method'!C16+'VC Method'!D15*'VC Method'!D16)))-'VC Method'!B5 | F6: ='VC Method'!B5/((('VC Method'!B5*$A6)/('VC Method'!B7*'VC Method'!B13*(F$4*'VC Method'!B14)*'VC Method'!B16+'VC Method'!B7*'VC Method'!C13*(F$4*'VC Method'!C14)*'VC Method'!C16+'VC Method'!B7*'VC Method'!D13*(F$4*'VC Method'!D14)*'VC Method'!D16))/(1-('VC Method'!B15*'VC Method'!B16+'VC Method'!C15*'VC Method'!C16+'VC Method'!D15*'VC Method'!D16)))-'VC Method'!B5
A7: 8 | B7: ='VC Method'!B5/((('VC Method'!B5*$A7)/('VC Method'!B7*'VC Method'!B13*(B$4*'VC Method'!B14)*'VC Method'!B16+'VC Method'!B7*'VC Method'!C13*(B$4*'VC Method'!C14)*'VC Method'!C16+'VC Method'!B7*'VC Method'!D13*(B$4*'VC Method'!D14)*'VC Method'!D16))/(1-('VC Method'!B15*'VC Method'!B16+'VC Method'!C15*'VC Method'!C16+'VC Method'!D15*'VC Method'!D16)))-'VC Method'!B5 | C7: ='VC Method'!B5/((('VC Method'!B5*$A7)/('VC Method'!B7*'VC Method'!B13*(C$4*'VC Method'!B14)*'VC Method'!B16+'VC Method'!B7*'VC Method'!C13*(C$4*'VC Method'!C14)*'VC Method'!C16+'VC Method'!B7*'VC Method'!D13*(C$4*'VC Method'!D14)*'VC Method'!D16))/(1-('VC Method'!B15*'VC Method'!B16+'VC Method'!C15*'VC Method'!C16+'VC Method'!D15*'VC Method'!D16)))-'VC Method'!B5 | D7: ='VC Method'!B5/((('VC Method'!B5*$A7)/('VC Method'!B7*'VC Method'!B13*(D$4*'VC Method'!B14)*'VC Method'!B16+'VC Method'!B7*'VC Method'!C13*(D$4*'VC Method'!C14)*'VC Method'!C16+'VC Method'!B7*'VC Method'!D13*(D$4*'VC Method'!D14)*'VC Method'!D16))/(1-('VC Method'!B15*'VC Method'!B16+'VC Method'!C15*'VC Method'!C16+'VC Method'!D15*'VC Method'!D16)))-'VC Method'!B5 | E7: ='VC Method'!B5/((('VC Method'!B5*$A7)/('VC Method'!B7*'VC Method'!B13*(E$4*'VC Method'!B14)*'VC Method'!B16+'VC Method'!B7*'VC Method'!C13*(E$4*'VC Method'!C14)*'VC Method'!C16+'VC Method'!B7*'VC Method'!D13*(E$4*'VC Method'!D14)*'VC Method'!D16))/(1-('VC Method'!B15*'VC Method'!B16+'VC Method'!C15*'VC Method'!C16+'VC Method'!D15*'VC Method'!D16)))-'VC Method'!B5 | F7: ='VC Method'!B5/((('VC Method'!B5*$A7)/('VC Method'!B7*'VC Method'!B13*(F$4*'VC Method'!B14)*'VC Method'!B16+'VC Method'!B7*'VC Method'!C13*(F$4*'VC Method'!C14)*'VC Method'!C16+'VC Method'!B7*'VC Method'!D13*(F$4*'VC Method'!D14)*'VC Method'!D16))/(1-('VC Method'!B15*'VC Method'!B16+'VC Method'!C15*'VC Method'!C16+'VC Method'!D15*'VC Method'!D16)))-'VC Method'!B5
A8: 9 | B8: ='VC Method'!B5/((('VC Method'!B5*$A8)/('VC Method'!B7*'VC Method'!B13*(B$4*'VC Method'!B14)*'VC Method'!B16+'VC Method'!B7*'VC Method'!C13*(B$4*'VC Method'!C14)*'VC Method'!C16+'VC Method'!B7*'VC Method'!D13*(B$4*'VC Method'!D14)*'VC Method'!D16))/(1-('VC Method'!B15*'VC Method'!B16+'VC Method'!C15*'VC Method'!C16+'VC Method'!D15*'VC Method'!D16)))-'VC Method'!B5 | C8: ='VC Method'!B5/((('VC Method'!B5*$A8)/('VC Method'!B7*'VC Method'!B13*(C$4*'VC Method'!B14)*'VC Method'!B16+'VC Method'!B7*'VC Method'!C13*(C$4*'VC Method'!C14)*'VC Method'!C16+'VC Method'!B7*'VC Method'!D13*(C$4*'VC Method'!D14)*'VC Method'!D16))/(1-('VC Method'!B15*'VC Method'!B16+'VC Method'!C15*'VC Method'!C16+'VC Method'!D15*'VC Method'!D16)))-'VC Method'!B5 | D8: ='VC Method'!B5/((('VC Method'!B5*$A8)/('VC Method'!B7*'VC Method'!B13*(D$4*'VC Method'!B14)*'VC Method'!B16+'VC Method'!B7*'VC Method'!C13*(D$4*'VC Method'!C14)*'VC Method'!C16+'VC Method'!B7*'VC Method'!D13*(D$4*'VC Method'!D14)*'VC Method'!D16))/(1-('VC Method'!B15*'VC Method'!B16+'VC Method'!C15*'VC Method'!C16+'VC Method'!D15*'VC Method'!D16)))-'VC Method'!B5 | E8: ='VC Method'!B5/((('VC Method'!B5*$A8)/('VC Method'!B7*'VC Method'!B13*(E$4*'VC Method'!B14)*'VC Method'!B16+'VC Method'!B7*'VC Method'!C13*(E$4*'VC Method'!C14)*'VC Method'!C16+'VC Method'!B7*'VC Method'!D13*(E$4*'VC Method'!D14)*'VC Method'!D16))/(1-('VC Method'!B15*'VC Method'!B16+'VC Method'!C15*'VC Method'!C16+'VC Method'!D15*'VC Method'!D16)))-'VC Method'!B5 | F8: ='VC Method'!B5/((('VC Method'!B5*$A8)/('VC Method'!B7*'VC Method'!B13*(F$4*'VC Method'!B14)*'VC Method'!B16+'VC Method'!B7*'VC Method'!C13*(F$4*'VC Method'!C14)*'VC Method'!C16+'VC Method'!B7*'VC Method'!D13*(F$4*'VC Method'!D14)*'VC Method'!D16))/(1-('VC Method'!B15*'VC Method'!B16+'VC Method'!C15*'VC Method'!C16+'VC Method'!D15*'VC Method'!D16)))-'VC Method'!B5
A9: 10 | B9: ='VC Method'!B5/((('VC Method'!B5*$A9)/('VC Method'!B7*'VC Method'!B13*(B$4*'VC Method'!B14)*'VC Method'!B16+'VC Method'!B7*'VC Method'!C13*(B$4*'VC Method'!C14)*'VC Method'!C16+'VC Method'!B7*'VC Method'!D13*(B$4*'VC Method'!D14)*'VC Method'!D16))/(1-('VC Method'!B15*'VC Method'!B16+'VC Method'!C15*'VC Method'!C16+'VC Method'!D15*'VC Method'!D16)))-'VC Method'!B5 | C9: ='VC Method'!B5/((('VC Method'!B5*$A9)/('VC Method'!B7*'VC Method'!B13*(C$4*'VC Method'!B14)*'VC Method'!B16+'VC Method'!B7*'VC Method'!C13*(C$4*'VC Method'!C14)*'VC Method'!C16+'VC Method'!B7*'VC Method'!D13*(C$4*'VC Method'!D14)*'VC Method'!D16))/(1-('VC Method'!B15*'VC Method'!B16+'VC Method'!C15*'VC Method'!C16+'VC Method'!D15*'VC Method'!D16)))-'VC Method'!B5 | D9: ='VC Method'!B5/((('VC Method'!B5*$A9)/('VC Method'!B7*'VC Method'!B13*(D$4*'VC Method'!B14)*'VC Method'!B16+'VC Method'!B7*'VC Method'!C13*(D$4*'VC Method'!C14)*'VC Method'!C16+'VC Method'!B7*'VC Method'!D13*(D$4*'VC Method'!D14)*'VC Method'!D16))/(1-('VC Method'!B15*'VC Method'!B16+'VC Method'!C15*'VC Method'!C16+'VC Method'!D15*'VC Method'!D16)))-'VC Method'!B5 | E9: ='VC Method'!B5/((('VC Method'!B5*$A9)/('VC Method'!B7*'VC Method'!B13*(E$4*'VC Method'!B14)*'VC Method'!B16+'VC Method'!B7*'VC Method'!C13*(E$4*'VC Method'!C14)*'VC Method'!C16+'VC Method'!B7*'VC Method'!D13*(E$4*'VC Method'!D14)*'VC Method'!D16))/(1-('VC Method'!B15*'VC Method'!B16+'VC Method'!C15*'VC Method'!C16+'VC Method'!D15*'VC Method'!D16)))-'VC Method'!B5 | F9: ='VC Method'!B5/((('VC Method'!B5*$A9)/('VC Method'!B7*'VC Method'!B13*(F$4*'VC Method'!B14)*'VC Method'!B16+'VC Method'!B7*'VC Method'!C13*(F$4*'VC Method'!C14)*'VC Method'!C16+'VC Method'!B7*'VC Method'!D13*(F$4*'VC Method'!D14)*'VC Method'!D16))/(1-('VC Method'!B15*'VC Method'!B16+'VC Method'!C15*'VC Method'!C16+'VC Method'!D15*'VC Method'!D16)))-'VC Method'!B5
A11: 中心(MOIC 8x, PS 8x)应≈VC Method主表概率加权投前估值。
A13: 表2：DCF 投前估值（万元，基准情景）= f(WACC × 永续增长率g)
A14: 行=WACC ↓ / 列=g → | B14: 0.01 | C14: 0.02 | D14: 0.03 | E14: 0.04 | F14: 0.05
A15: 0.14 | B15: =(DCF!B29/(1+$A15)^DCF!B43+DCF!C29/(1+$A15)^DCF!C43+DCF!D29/(1+$A15)^DCF!D43+DCF!E29/(1+$A15)^DCF!E43+DCF!F29/(1+$A15)^DCF!F43+DCF!F29*(1+B$14)/($A15-B$14)/(1+$A15)^DCF!F43)-DCF!B38-DCF!B57 | C15: =(DCF!B29/(1+$A15)^DCF!B43+DCF!C29/(1+$A15)^DCF!C43+DCF!D29/(1+$A15)^DCF!D43+DCF!E29/(1+$A15)^DCF!E43+DCF!F29/(1+$A15)^DCF!F43+DCF!F29*(1+C$14)/($A15-C$14)/(1+$A15)^DCF!F43)-DCF!B38-DCF!B57 | D15: =(DCF!B29/(1+$A15)^DCF!B43+DCF!C29/(1+$A15)^DCF!C43+DCF!D29/(1+$A15)^DCF!D43+DCF!E29/(1+$A15)^DCF!E43+DCF!F29/(1+$A15)^DCF!F43+DCF!F29*(1+D$14)/($A15-D$14)/(1+$A15)^DCF!F43)-DCF!B38-DCF!B57 | E15: =(DCF!B29/(1+$A15)^DCF!B43+DCF!C29/(1+$A15)^DCF!C43+DCF!D29/(1+$A15)^DCF!D43+DCF!E29/(1+$A15)^DCF!E43+DCF!F29/(1+$A15)^DCF!F43+DCF!F29*(1+E$14)/($A15-E$14)/(1+$A15)^DCF!F43)-DCF!B38-DCF!B57 | F15: =(DCF!B29/(1+$A15)^DCF!B43+DCF!C29/(1+$A15)^DCF!C43+DCF!D29/(1+$A15)^DCF!D43+DCF!E29/(1+$A15)^DCF!E43+DCF!F29/(1+$A15)^DCF!F43+DCF!F29*(1+F$14)/($A15-F$14)/(1+$A15)^DCF!F43)-DCF!B38-DCF!B57
A16: 0.16 | B16: =(DCF!B29/(1+$A16)^DCF!B43+DCF!C29/(1+$A16)^DCF!C43+DCF!D29/(1+$A16)^DCF!D43+DCF!E29/(1+$A16)^DCF!E43+DCF!F29/(1+$A16)^DCF!F43+DCF!F29*(1+B$14)/($A16-B$14)/(1+$A16)^DCF!F43)-DCF!B38-DCF!B57 | C16: =(DCF!B29/(1+$A16)^DCF!B43+DCF!C29/(1+$A16)^DCF!C43+DCF!D29/(1+$A16)^DCF!D43+DCF!E29/(1+$A16)^DCF!E43+DCF!F29/(1+$A16)^DCF!F43+DCF!F29*(1+C$14)/($A16-C$14)/(1+$A16)^DCF!F43)-DCF!B38-DCF!B57 | D16: =(DCF!B29/(1+$A16)^DCF!B43+DCF!C29/(1+$A16)^DCF!C43+DCF!D29/(1+$A16)^DCF!D43+DCF!E29/(1+$A16)^DCF!E43+DCF!F29/(1+$A16)^DCF!F43+DCF!F29*(1+D$14)/($A16-D$14)/(1+$A16)^DCF!F43)-DCF!B38-DCF!B57 | E16: =(DCF!B29/(1+$A16)^DCF!B43+DCF!C29/(1+$A16)^DCF!C43+DCF!D29/(1+$A16)^DCF!D43+DCF!E29/(1+$A16)^DCF!E43+DCF!F29/(1+$A16)^DCF!F43+DCF!F29*(1+E$14)/($A16-E$14)/(1+$A16)^DCF!F43)-DCF!B38-DCF!B57 | F16: =(DCF!B29/(1+$A16)^DCF!B43+DCF!C29/(1+$A16)^DCF!C43+DCF!D29/(1+$A16)^DCF!D43+DCF!E29/(1+$A16)^DCF!E43+DCF!F29/(1+$A16)^DCF!F43+DCF!F29*(1+F$14)/($A16-F$14)/(1+$A16)^DCF!F43)-DCF!B38-DCF!B57
A17: 0.18 | B17: =(DCF!B29/(1+$A17)^DCF!B43+DCF!C29/(1+$A17)^DCF!C43+DCF!D29/(1+$A17)^DCF!D43+DCF!E29/(1+$A17)^DCF!E43+DCF!F29/(1+$A17)^DCF!F43+DCF!F29*(1+B$14)/($A17-B$14)/(1+$A17)^DCF!F43)-DCF!B38-DCF!B57 | C17: =(DCF!B29/(1+$A17)^DCF!B43+DCF!C29/(1+$A17)^DCF!C43+DCF!D29/(1+$A17)^DCF!D43+DCF!E29/(1+$A17)^DCF!E43+DCF!F29/(1+$A17)^DCF!F43+DCF!F29*(1+C$14)/($A17-C$14)/(1+$A17)^DCF!F43)-DCF!B38-DCF!B57 | D17: =(DCF!B29/(1+$A17)^DCF!B43+DCF!C29/(1+$A17)^DCF!C43+DCF!D29/(1+$A17)^DCF!D43+DCF!E29/(1+$A17)^DCF!E43+DCF!F29/(1+$A17)^DCF!F43+DCF!F29*(1+D$14)/($A17-D$14)/(1+$A17)^DCF!F43)-DCF!B38-DCF!B57 | E17: =(DCF!B29/(1+$A17)^DCF!B43+DCF!C29/(1+$A17)^DCF!C43+DCF!D29/(1+$A17)^DCF!D43+DCF!E29/(1+$A17)^DCF!E43+DCF!F29/(1+$A17)^DCF!F43+DCF!F29*(1+E$14)/($A17-E$14)/(1+$A17)^DCF!F43)-DCF!B38-DCF!B57 | F17: =(DCF!B29/(1+$A17)^DCF!B43+DCF!C29/(1+$A17)^DCF!C43+DCF!D29/(1+$A17)^DCF!D43+DCF!E29/(1+$A17)^DCF!E43+DCF!F29/(1+$A17)^DCF!F43+DCF!F29*(1+F$14)/($A17-F$14)/(1+$A17)^DCF!F43)-DCF!B38-DCF!B57
A18: 0.2 | B18: =(DCF!B29/(1+$A18)^DCF!B43+DCF!C29/(1+$A18)^DCF!C43+DCF!D29/(1+$A18)^DCF!D43+DCF!E29/(1+$A18)^DCF!E43+DCF!F29/(1+$A18)^DCF!F43+DCF!F29*(1+B$14)/($A18-B$14)/(1+$A18)^DCF!F43)-DCF!B38-DCF!B57 | C18: =(DCF!B29/(1+$A18)^DCF!B43+DCF!C29/(1+$A18)^DCF!C43+DCF!D29/(1+$A18)^DCF!D43+DCF!E29/(1+$A18)^DCF!E43+DCF!F29/(1+$A18)^DCF!F43+DCF!F29*(1+C$14)/($A18-C$14)/(1+$A18)^DCF!F43)-DCF!B38-DCF!B57 | D18: =(DCF!B29/(1+$A18)^DCF!B43+DCF!C29/(1+$A18)^DCF!C43+DCF!D29/(1+$A18)^DCF!D43+DCF!E29/(1+$A18)^DCF!E43+DCF!F29/(1+$A18)^DCF!F43+DCF!F29*(1+D$14)/($A18-D$14)/(1+$A18)^DCF!F43)-DCF!B38-DCF!B57 | E18: =(DCF!B29/(1+$A18)^DCF!B43+DCF!C29/(1+$A18)^DCF!C43+DCF!D29/(1+$A18)^DCF!D43+DCF!E29/(1+$A18)^DCF!E43+DCF!F29/(1+$A18)^DCF!F43+DCF!F29*(1+E$14)/($A18-E$14)/(1+$A18)^DCF!F43)-DCF!B38-DCF!B57 | F18: =(DCF!B29/(1+$A18)^DCF!B43+DCF!C29/(1+$A18)^DCF!C43+DCF!D29/(1+$A18)^DCF!D43+DCF!E29/(1+$A18)^DCF!E43+DCF!F29/(1+$A18)^DCF!F43+DCF!F29*(1+F$14)/($A18-F$14)/(1+$A18)^DCF!F43)-DCF!B38-DCF!B57
A19: 0.22 | B19: =(DCF!B29/(1+$A19)^DCF!B43+DCF!C29/(1+$A19)^DCF!C43+DCF!D29/(1+$A19)^DCF!D43+DCF!E29/(1+$A19)^DCF!E43+DCF!F29/(1+$A19)^DCF!F43+DCF!F29*(1+B$14)/($A19-B$14)/(1+$A19)^DCF!F43)-DCF!B38-DCF!B57 | C19: =(DCF!B29/(1+$A19)^DCF!B43+DCF!C29/(1+$A19)^DCF!C43+DCF!D29/(1+$A19)^DCF!D43+DCF!E29/(1+$A19)^DCF!E43+DCF!F29/(1+$A19)^DCF!F43+DCF!F29*(1+C$14)/($A19-C$14)/(1+$A19)^DCF!F43)-DCF!B38-DCF!B57 | D19: =(DCF!B29/(1+$A19)^DCF!B43+DCF!C29/(1+$A19)^DCF!C43+DCF!D29/(1+$A19)^DCF!D43+DCF!E29/(1+$A19)^DCF!E43+DCF!F29/(1+$A19)^DCF!F43+DCF!F29*(1+D$14)/($A19-D$14)/(1+$A19)^DCF!F43)-DCF!B38-DCF!B57 | E19: =(DCF!B29/(1+$A19)^DCF!B43+DCF!C29/(1+$A19)^DCF!C43+DCF!D29/(1+$A19)^DCF!D43+DCF!E29/(1+$A19)^DCF!E43+DCF!F29/(1+$A19)^DCF!F43+DCF!F29*(1+E$14)/($A19-E$14)/(1+$A19)^DCF!F43)-DCF!B38-DCF!B57 | F19: =(DCF!B29/(1+$A19)^DCF!B43+DCF!C29/(1+$A19)^DCF!C43+DCF!D29/(1+$A19)^DCF!D43+DCF!E29/(1+$A19)^DCF!E43+DCF!F29/(1+$A19)^DCF!F43+DCF!F29*(1+F$14)/($A19-F$14)/(1+$A19)^DCF!F43)-DCF!B38-DCF!B57
A21: 中心(WACC 18%, g 3%)应≈DCF主表隐含投前估值(基准情景,选择器=2时)。

Sheet 融资与股权
A1: 融资与股权测算（天使轮及后续稀释路径）
A2: 基于BP融资计划测算本轮股比及天使投资人至IPO的稀释路径。各轮投前估值为分析师假设，单位：万元。
A4: 一、本轮（天使轮）股权结构
A5: 本轮投前估值（取主模型中枢） | B5: =摘要与结论!B15
A6: 本轮投资额 | B6: 4500
A7: 本轮投后估值 | B7: =B5+B6
A8: 天使投资人本轮股比 | B8: =B6/B7
A9: 创始团队(含期权池)本轮后股比 | B9: =1-B8
A11: 二、后续融资轮次（BP计划）与稀释
A12: 轮次 | B12: 年份 | C12: 融资额 | D12: 投前估值 | E12: 投后估值 | F12: 新投资人股比 | G12: 天使累计股比
A13: 天使轮(本轮) | B13: 2026 | C13: =B6 | D13: =B5 | E13: =B7 | F13: =B8 | G13: =B8
A14: Pre-A | B14: 2028 | C14: 8000 | D14: 40000 | E14: =D14+C14 | F14: =C14/E14 | G14: =G13*(1-F14)
A15: A轮 | B15: 2029 | C15: 12000 | D15: 90000 | E15: =D15+C15 | F15: =C15/E15 | G15: =G14*(1-F15)
A16: B轮 | B16: 2030 | C16: 55000 | D16: 250000 | E16: =D16+C16 | F16: =C16/E16 | G16: =G15*(1-F16)
A17: IPO时天使累计稀释 | B17: =1-G16/B8 | C17: (相对本轮股比的累计稀释)
A19: 三、天使投资人退出回报测算
A20: 退出年天使持股比例 | B20: =G16
A21: 退出股权价值(VC概率加权,万元) | B21: ='VC Method'!E22
A22: 天使退出所得(万元) | B22: =B20*B21
A23: 对本轮投资的回报倍数 MOIC | B23: =B22/B6
A24: 对应年化IRR(约2031-2026) | B24: =(B23)^(1/5)-1
A26: 注：未建模优先清算权、参与权、反稀释与期权池扩张的额外稀释；各轮投前估值为假设值,尽调需以实际条款与市场数据替换。

Sheet 假设与来源
A1: 关键假设与资料来源
A3: 一、数据分级
A4: 类别 | B4: 内容 | C4: 说明
A5: 公司提供(BP) | B5: 营收路径、融资计划、里程碑、技术验证数据 | C5: BP 2026.6规划口径,未经审计
A6: 公开来源 | B6: 行业市场规模、CAGR、可比公司 | C6: QYResearch/PW/YHResearch等(BP引用)
A7: 行业基准 | B7: 天使轮投前区间、MOIC、退出倍数 | C7: industry-benchmarks.md
A8: 分析师判断 | B8: 情景概率、PS折价、稀释、WACC、利润率、CapEx | C8: 本模型假设,需尽调替换
A9: 敏感性 | B9: MOIC×PS、WACC×g 两张网格 | C9: 见敏感性分析表
A11: 二、核心假设汇总
A12: 本轮投资额 | B12: 4,500 万元 | C12: BP一期投资
A13: 退出年份/持有期 | B13: 2031 / 约5年 | C13: BP科创板申报
A14: 退出年营收(BP) | B14: 100,000 万元(10亿) | C14: BP 2031预测
A15: 目标MOIC | B15: 8x | C15: 天使基准10x,硬科技+政策综合调整
A16: 可比PS倍数 | B16: 8x (EV/Rev) | C16: 半导体硬科技3-10x中枢
A17: 早期近端PS倍数(可比估值) | B17: 12x | C17: 可比区间上沿,早期高成长溢价
A18: 可比估值·近端营收 | B18: 3,000 万元(2028E) | C18: BP预测
A19: 退出PS折价(基准) | B19: 60% | C19: 天使轮退出流动性折价
A20: 至IPO累计稀释(基准) | B20: 55% | C20: 多轮融资摊薄
A21: 情景概率 | B21: 乐观20%/基准55%/悲观25% | C21: 分析师判断
A22: WACC(基准) | B22: 18% | C22: 一级市场含创业失败风险
A23: 永续增长率(基准) | B23: 3% | C23: 新兴行业GDP+
A24: 方法权重 | B24: VC40/Scorecard30/Berkus20/Comps10 | C24: 天使轮加权规则
A26: 三、资料来源
A27: 《臻陶科技-泛半导体陶瓷材料及部件》项目BP,2026年6月规划口径
A28: 李明远教授团队实验数据与研究资料(BP引用)
A29: QYResearch / PW Consulting / YHResearch / GGI / 弗若斯特沙利文(BP引用)
A30: 观研报告网、东方财富、TrendForce、券商研报(BP引用)
A31: primary-market-valuation 技能:vc-methodology-reference.md、industry-benchmarks.md
A33: 免责声明：本模型为基于BP的分析性估值,用于项目研究与融资谈判准备,不构成审计、正式评估或投资建议,不对预测或交易结果作保证。
